<?xml version='1.0'?>
<!-- 
This model describes a mechanism to be attached to the "world" (at the base),
with six degrees of freedom: three translational and three rotational. Each
degree of freedom is realized through a single degree of freedom joint- revolute
or prismatic- connecting two low-mass (1e-4 kg) links. 
-->

<sdf version='1.6'>
  <model name='BipedalSpringMass'>
    
    <!-- GROUND -->  
      
    <link name='ground'>
      <pose frame=''>0 0 -5 0 0.0 0.</pose>
      <inertial>
        <pose frame=''>0 0 0 0 0.0 0.</pose>
        <mass>0</mass>
        <inertia>
          <ixx>0</ixx>
          <ixy>0</ixy>
          <ixz>0</ixz>
          <iyy>0</iyy>
          <iyz>0</iyz>
          <izz>0</izz>
        </inertia>
      </inertial>
      <collision name='ground_collision'>
        <pose frame=''>0 0 0 0 0.0 0.</pose>
        <geometry>
          <box>
            <size>100.0 100.0 10.0</size>
          </box>
        </geometry>
      </collision>
      <visual name='ground_visual'>
        <pose frame=''>0 0 0 0 0.0 0.</pose>
        <geometry>
          <box>
            <size>100.0 100.0 10.0</size>
          </box>
        </geometry>
        <material>
          <diffuse>0.54 0.54 0.54 0.9</diffuse>
        </material>
      </visual>
    </link>

      
      
    <!-- BODY -->    
      
    <link name='body_pre_z'/>
    <link name='body_pre_theta'/>

    <link name='body'>
      <pose frame=''>0 0 0 0 0 0</pose>
      <inertial>
        <pose frame=''>0 0 0 0 0 0</pose>
        <mass>.1</mass>
        <inertia>
          <ixx>100.0</ixx>
          <ixy>0</ixy>
          <ixz>0</ixz>
          <iyy>100.0</iyy>
          <iyz>0</iyz>
          <izz>100.0</izz>
        </inertia>
      </inertial>
      
      <visual name='body_visual'>
        <pose frame=''>0 0 0 0 0 0</pose>
        <geometry>
          <sphere>
             <radius> 0.3 </radius>  
          </sphere>
        </geometry>
        <material>
          <diffuse>0.64 0.12 0.15 0.9</diffuse>
        </material>
      </visual>

      
      <!-- 
      <visual name='body_visual_nx'>
        <pose frame=''>-.5 0 0 0 0 0</pose>
        <geometry>
          <box>
            <size>0.1 1.0 0.5</size>
          </box>
        </geometry>
        <material>
          <diffuse>0.64 0.12 0.15 0.9</diffuse>
        </material>
      </visual>

      <visual name='body_visual_ny'>
        <pose frame=''>0 -.5 0 0 0 0</pose>
        <geometry>
          <box>
            <size>1.0 0.1 0.5</size>
          </box>
        </geometry>
        <material>
          <diffuse>0.64 0.12 0.15 0.9</diffuse>
        </material>
      </visual>
      
      <visual name='body_visual_px'>
        <pose frame=''>.5 0 0 0 0 0</pose>
        <geometry>
          <box>
            <size>0.1 1.0 0.5</size>
          </box>
        </geometry>
        <material>
          <diffuse>0.64 0.12 0.15 0.9</diffuse>
        </material>
      </visual>
      

      <visual name='body_visual_py'>
        <pose frame=''>0 .5 0 0 0 0</pose>
        <geometry>
          <box>
            <size>1.0 0.1 0.5</size>
          </box>
        </geometry>
        <material>
          <diffuse>0.64 0.12 0.15 0.9</diffuse>
        </material>
      </visual>
 
      <collision name='body_collision_nx'>
        <pose frame=''>-.5 0 0 0 0 0</pose>
        <geometry>
          <box>
            <size>0.1 1.0 0.5</size>
          </box>
        </geometry>
      </collision>
      <collision name='body_collision_px'>
        <pose frame=''>.5 0 0 0 0 0</pose>
        <geometry>
          <box>
            <size>0.1 1.0 0.5</size>
          </box>
        </geometry>
      </collision>
      -->
        
    </link>

    <joint name='body_x' type='prismatic'>
      <child>body_pre_z</child>
      <parent>ground</parent>
      <axis>
        <xyz>1 0 0</xyz>
        <limit>
          <effort>0.0</effort>
        </limit>
        <dynamics>
          <damping>0</damping>
          <friction>0</friction>
          <spring_reference>0</spring_reference>
          <spring_stiffness>0</spring_stiffness>
        </dynamics>
        <use_parent_model_frame>1</use_parent_model_frame>
      </axis>
    </joint>
      
    <joint name='body_z' type='prismatic'>
      <child>body_pre_theta</child>
      <parent>body_pre_z</parent>
      <axis>
        <xyz>0 0 1</xyz>
        <limit>
          <effort>0.0</effort>
        </limit>
        <dynamics>
          <damping>0</damping>
          <friction>0</friction>
          <spring_reference>0</spring_reference>
          <spring_stiffness>0</spring_stiffness>
        </dynamics>
        <use_parent_model_frame>1</use_parent_model_frame>
      </axis>
    </joint>
    <joint name='body_theta' type='revolute'>
      <child>body</child>
      <parent>body_pre_theta</parent>
      <axis>
        <xyz>0 1 0</xyz>
        <limit>
          <effort>0.0</effort>
        </limit>
        <dynamics>
          <damping>0</damping>
          <friction>0</friction>
          <spring_reference>0</spring_reference>
          <spring_stiffness>0</spring_stiffness>
        </dynamics>
        <use_parent_model_frame>1</use_parent_model_frame>
      </axis>
    </joint>

      
      
    <!-- LEG 1 -->    
      
    <link name='leg1_thigh'>
      <visual name='body_visual_ny'>
        <pose frame=''>0 0 0 0 0 0</pose>
        <geometry>
          <box>
            <size>0.1 0.1 0.75</size>
          </box>
        </geometry>
        <material>
          <diffuse>0.9 0.9 0.9 0.9</diffuse>
        </material>
      </visual>
    </link>
      
    <joint name='thigh1' type='revolute'>
      <child>leg1_thigh</child>
      <parent>body</parent>
      <axis>
        <xyz>0 1 0</xyz>
        <dynamics>
          <damping>1.</damping>
          <friction>0</friction>
          <spring_reference>0</spring_reference>
          <spring_stiffness>0</spring_stiffness>
        </dynamics>
        <use_parent_model_frame>1</use_parent_model_frame>
      </axis>
    </joint>
      
    <joint name='extension1' type='prismatic'>
      <child>foot1</child>
      <parent>leg1_thigh</parent>
      <axis>
        <xyz>0 0 -1</xyz>
        <limit>
          <upper>.8</upper>
          <stiffness>10000</stiffness>
          <dissipation>1.0</dissipation>
        </limit>
        <dynamics>
          <damping>0</damping>
          <friction>0</friction>
          <spring_reference>0</spring_reference>
          <spring_stiffness>0</spring_stiffness>
        </dynamics>
        <use_parent_model_frame>1</use_parent_model_frame>
      </axis>
    </joint>  

    <link name='foot1'>
      <pose frame=''>0 0 0.0 0 0 0</pose>
      <inertial>
        <pose frame=''>0 0 0 0 0 0</pose>
        <mass>0.01</mass>
        <inertia>
          <ixx>0.01</ixx>
          <ixy>0</ixy>
          <ixz>0</ixz>
          <iyy>0.01</iyy>
          <iyz>0</iyz>
          <izz>0.01</izz>
        </inertia>
      </inertial>
      <collision name='foot1_collision'>
        <pose frame=''>0 1 0 0 0 0</pose>
        <geometry>
          <box>
            <size>0.05 0.05 2.0</size>
          </box>
        </geometry>
      </collision>
      <visual name='foot1_visual'>
        <pose frame=''>0 0 0 0 0 0</pose>
        <geometry>
          <box>
            <size>0.05 0.05 2.0</size>
          </box>
        </geometry>
        <material>
          <diffuse>0.9 0.9 0.9 0.9</diffuse>
        </material>
      </visual>
    </link>
       
      
    <!-- LEG 2 -->  
      
    <link name='leg2_thigh'>
      <visual name='body_visual_ny'>
        <pose frame=''>0 0.0 0 0 0 0</pose>
        <geometry>
          <box>
            <size>0.1 0.1 0.75</size>
          </box>
        </geometry>
        <material>
          <diffuse>0.64 0.12 0.15 0.9</diffuse>
        </material>
      </visual>
    </link>
      
    <joint name='thigh2' type='revolute'>
      <child>leg2_thigh</child>
      <parent>body</parent>
      <axis>
        <xyz>0 1 0</xyz>
        <dynamics>
          <damping>1.</damping>
          <friction>0</friction>
          <spring_reference>0</spring_reference>
          <spring_stiffness>0</spring_stiffness>
        </dynamics>
        <use_parent_model_frame>1</use_parent_model_frame>
      </axis>
    </joint>

    <joint name='extension2' type='prismatic'>
      <child>foot2</child>
      <parent>leg2_thigh</parent>
      <axis>
        <xyz>0 0 -1</xyz>
        <limit>
          <upper>0.8</upper>
          <stiffness>10000</stiffness>
          <dissipation>1.0</dissipation>
        </limit>
        <dynamics>
          <damping>0</damping>
          <friction>0</friction>
          <spring_reference>0</spring_reference>
          <spring_stiffness>0</spring_stiffness>
        </dynamics>
        <use_parent_model_frame>1</use_parent_model_frame>
      </axis>
    </joint>   
      
    <link name='foot2'>
      <pose frame=''>0 0 0.0 0 0 0</pose>
      <inertial>
        <pose frame=''>0 0 0 0 0 0</pose>
        <mass>0.01</mass>
        <inertia>
          <ixx>0.01</ixx>
          <ixy>0</ixy>
          <ixz>0</ixz>
          <iyy>0.01</iyy>
          <iyz>0</iyz>
          <izz>0.01</izz>
        </inertia>
      </inertial>
      <collision name='foot2_collision'>
        <pose frame=''>0 -1 0 0 0 0</pose>
        <geometry>
          <box>
            <size>0.05 0.05 2.0</size>
          </box>
        </geometry>
      </collision>
      <visual name='foot2_visual'>
        <pose frame=''>0 0 0 0 0 0</pose>
        <geometry>
          <box>
            <size>0.05 0.05 2.0</size>
          </box>
        </geometry>
        <material>
          <diffuse>0.64 0.12 0.15 0.9</diffuse>
        </material>
      </visual>
    </link>
      

  </model>
</sdf>